<mujoco>
    <worldbody>
        <light name="top" pos="0 0 3"/>
        <body name="link_1">
            <joint name="tx" type="slide" axis="1 0 0"/>
            <inertial pos="0 0 0" mass="0.006" diaginertia="0.00005 0.000065 0.000025"/>
            <body name="link_2">
                <joint name="ty" type="slide" axis="0 1 0"/>
                <inertial pos="0 0 0" mass="0.006" diaginertia="0.00005 0.000065 0.000025"/>
                <body name="object">
                    <joint name="tz" type="slide" axis="0 0 1"/>
                    <site name="ft_sen"/>
                    <geom name="red_box" type="box" size=".05 .1 .15" rgba="1 0 0 1"/>
                </body>
            </body>
        </body>
    </worldbody>

    <actuator>
        <motor name="mtr_tx" joint="tx"/>
        <motor name="mtr_ty" joint="ty"/>
        <motor name="mtr_tz" joint="tz"/>
    </actuator>

    <sensor>
        <jointpos name="tx" joint="tx"/>
        <jointpos name="ty" joint="ty"/>
        <jointpos name="tz" joint="tz"/>
        <jointvel name="dtx" joint="tx"/>
        <jointvel name="dty" joint="ty"/>
        <jointvel name="dtz" joint="tz"/>
        <actuatorfrc name="frc_tx" actuator="mtr_tx"/>
        <actuatorfrc name="frc_ty" actuator="mtr_ty"/>
        <actuatorfrc name="frc_tz" actuator="mtr_tz"/>
    </sensor>

    <visual>
        <global offwidth="960" offheight="600"/>
    </visual>
</mujoco>